<?xml version="1.0"?>
<!-- URDF placeholder file for omnibot. -->
<!-- URDF Mesh -->
<!-- Author: Sreejith S -->
<!-- Sat 26 Dec 2020 21:33:41 IST -->

<robot name="omnibot">

    <!--Materials color predefined-->
  <material name="black">
    <color rgba="0.0 0.0 0.0 1.0"/>
  </material>
  <material name="blue">
    <color rgba="0 0 0.8 1.0"/>
  </material>
  <material name="green">
    <color rgba="0.0 0.8 0.0 1.0"/>
  </material>
  <material name="red">
    <color rgba="1.0 0 0 1.0"/>
  </material>
  <material name="white">
    <color rgba="1.0 1.0 1.0 1.0"/>
  </material>

  <link name="base_footprint">
    <!--<inertial>-->
      <!--<mass value="0.0001"/>-->
      <!--<origin xyz="0 0 0"/>-->
      <!--<inertia ixx="0.0" ixy="0.0" ixz="0.0" iyy="0.0" iyz="0.0" izz="0.0"/>-->
    <!--</inertial>-->
    <visual>
      <origin rpy="0 0 0" xyz="0 0 0"/>
      <geometry>
        <box size="0.001 0.001 0.001"/>
      </geometry>
    </visual>
  </link>

    <link name="base_link">
        <visual>
            <origin rpy="1.57079632679 0 1.57079632679 " xyz="0 0 0"/>
            <geometry>
                <mesh filename="package://omnibot_description/meshes/Robot_chassis.STL" scale="0.001 0.001 0.001"/>
            </geometry>
            <material name="red"/>
        </visual>
        <inertial>
            <origin rpy="1.57079632679 0 1.57079632679 " xyz="0 0 0"/>
            <mass value="1"/>
            <inertia ixx="0.015" ixy="0" ixz="0" iyy="0.0375" iyz="0" izz="0.0375"/>
        </inertial>
        <collision>
            <origin rpy="0 0 0" xyz="0 0 0"/>
            <geometry>
                <box size="0.15 .20 .054"/>
            </geometry>
        </collision>
    </link>

    <link name="front_castor_of_wheel">
        <visual>
            <origin rpy="0 0 0" xyz="0 0 -0.009375"/>
            <geometry>
                <cylinder radius="0.00625" length="0.01875"/>
            </geometry>
            <material name="white"/>
        </visual>
        <inertial>
            <origin rpy="0 0 0" xyz="0 0 -0.009375"/>
            <mass value="1"/>
            <inertia ixx="0.00083" ixy="0" ixz="0" iyy="0.00083" iyz="0" izz="0.000167"/>
        </inertial>
         <collision>
            <origin rpy="0 0 0" xyz="0 0 -0.009375"/>
            <geometry>
                <cylinder radius="0.00625" length="0.01875"/>
            </geometry>
        </collision>
    </link>

    <link name="front_wheel">
        <visual>
            <origin rpy="0 0 0" xyz="0 0 0"/>
            <geometry>
                <sphere radius="0.00625"/>
            </geometry>
            <material name="blue"/>
        </visual>
        <inertial>
            <mass value="1"/>
            <inertia ixx="5.1458e-5" ixy="0" ixz="0" iyy="5.1458e-5" iyz="0.0" izz="6.125e-5"/>
        </inertial>
        <collision>
            <geometry>
                <sphere radius="0.00625"/>
            </geometry>
        </collision>
    </link>

    <link name="right_wheel">
        <visual>
            <origin rpy="0 0 0" xyz="0 0 0"/>
            <geometry>
                <!--<cylinder radius="0.035" length="0.05"/>-->
                <mesh filename="package://omnibot_description/meshes/wheel.STL" scale="1 1 1"/>
            </geometry>
            <material name="green"/>
        </visual>
        <inertial>
            <mass value="1"/>
            <inertia ixx="5.1458e-5" ixy="0" ixz="0" iyy="5.1458e-5" iyz="0.0" izz="6.125e-5"/>
        </inertial>
        <collision>
            <origin rpy="0 0 0" xyz="0 0 0.0125"/>
            <geometry>
                <cylinder radius="0.032" length="0.025"/>
            </geometry>
        </collision>
    </link>

    <link name="left_wheel">
        <visual>
            <origin rpy="0 0 0" xyz="0 0 0"/>
            <geometry>
                <mesh filename="package://omnibot_description/meshes/wheel.STL" scale="1 1 1"/>
                <!--<cylinder radius="0.035" length="0.05"/>-->
            </geometry>
            <material name="green"/>
        </visual>
        <inertial>
            <mass value="1"/>
            <inertia ixx="5.1458e-5" ixy="0" ixz="0" iyy="5.1458e-5" iyz="0.0" izz="6.125e-5"/>
        </inertial>
        <collision>
            <origin rpy="0 0 0" xyz="0 0 0.0125"/>
            <geometry>
                <cylinder radius="0.032" length="0.025"/>
            </geometry>
        </collision>
    </link>

    <joint name="base_foorprint_to_base_link" type="fixed">
        <origin xyz="0 0 0.0512"/>
        <parent link="base_footprint"/>
        <child link="base_link"/>
    </joint>

    <joint name="base_to_castor_socket" type="fixed">
        <origin xyz="-0.05 0 -0.025"/>
        <parent link="base_link"/>
        <child link="front_castor_of_wheel"/>
    </joint>

    <joint name="castor_socket_to_front_wheel" type="fixed">
        <origin xyz="0 0 -0.01875"/>
        <parent link="front_castor_of_wheel"/>
        <child link="front_wheel"/>
    </joint>

    <joint name="base_link_to_right_wheel" type="continuous">
        <origin rpy="1.57079632679 0  0 " xyz="0.0267 0.13 -0.02"/>
        <axis xyz="0 0 1 "/>
        <parent link="base_link"/>
        <child link="right_wheel"/>
    </joint>

    <joint name="base_link_to_left_wheel" type="continuous">
        <origin rpy="-1.57079632679 0  0 " xyz="0.0267 -0.13 -0.02"/>
        <axis xyz="0 0 -1 "/>
        <parent link="base_link"/>
        <child link="left_wheel"/>
    </joint>

</robot>
